<?xml version="1.0" encoding="UTF-8"?>
<testsuite name="helloworld_tests.FlaskTestCase-20211219173546" tests="1" file="helloworld_tests.py" time="0.016" timestamp="2021-12-19T17:35:48" failures="1" errors="0" skipped="0">
	<testcase classname="helloworld_tests.FlaskTestCase" name="test_correct_login" time="0.016" timestamp="2021-12-19T17:35:48">
		<failure type="AssertionError" message="b'Invalid Email and/or Password' not found in b'&lt;!DOCTYPE HTML PUBLIC &quot;-//W3C//DTD HTML 3.2 Final//EN&quot;&gt;\n&lt;title&gt;400 Bad Request&lt;/title&gt;\n&lt;h1&gt;Bad Request&lt;/h1&gt;\n&lt;p&gt;The browser (or proxy) sent a request that this server could not understand.&lt;/p&gt;\n'"><![CDATA[Traceback (most recent call last):
  File "c:\users\hp\appdata\local\programs\python\python38\lib\unittest\case.py", line 60, in testPartExecutor
    yield
  File "c:\users\hp\appdata\local\programs\python\python38\lib\unittest\case.py", line 676, in run
    self._callTestMethod(testMethod)
  File "c:\users\hp\appdata\local\programs\python\python38\lib\unittest\case.py", line 633, in _callTestMethod
    method()
  File "c:\users\hp\desktop\builder\profiling\src\unittest\python\helloworld_tests.py", line 17, in test_correct_login
    self.assertIn(b'Invalid Email and/or Password', response.data)
  File "c:\users\hp\appdata\local\programs\python\python38\lib\unittest\case.py", line 1179, in assertIn
    self.fail(self._formatMessage(msg, standardMsg))
  File "c:\users\hp\appdata\local\programs\python\python38\lib\unittest\case.py", line 753, in fail
    raise self.failureException(msg)
AssertionError: b'Invalid Email and/or Password' not found in b'<!DOCTYPE HTML PUBLIC "-//W3C//DTD HTML 3.2 Final//EN">\n<title>400 Bad Request</title>\n<h1>Bad Request</h1>\n<p>The browser (or proxy) sent a request that this server could not understand.</p>\n'
]]></failure>
	</testcase>
</testsuite>
