<?xml version="1.0" encoding="UTF-8"?>
<testsuite name="helloworld_tests.HelloWorldTest-20211219163536" tests="1" file="helloworld_tests.py" time="0.221" timestamp="2021-12-19T16:35:38" failures="0" errors="1" skipped="0">
	<testcase classname="helloworld_tests.HelloWorldTest" name="test_valid_user_registration" time="0.221" timestamp="2021-12-19T16:35:38">
		<error type="NameError" message="name 'response' is not defined"><![CDATA[Traceback (most recent call last):
  File "c:\users\hp\appdata\local\programs\python\python38\lib\unittest\case.py", line 60, in testPartExecutor
    yield
  File "c:\users\hp\appdata\local\programs\python\python38\lib\unittest\case.py", line 676, in run
    self._callTestMethod(testMethod)
  File "c:\users\hp\appdata\local\programs\python\python38\lib\unittest\case.py", line 633, in _callTestMethod
    method()
  File "c:\users\hp\desktop\builder\profiling\src\unittest\python\helloworld_tests.py", line 11, in test_valid_user_registration
    self.assertEqual(response.status_code, 200)
NameError: name 'response' is not defined
]]></error>
	</testcase>
</testsuite>
