<?xml version="1.0" encoding="UTF-8"?>
<testsuite name="helloworld_tests.HelloWorldTest-20211219171112" tests="1" file="helloworld_tests.py" time="0.000" timestamp="2021-12-19T17:11:14" failures="0" errors="1" skipped="0">
	<testcase classname="helloworld_tests.HelloWorldTest" name="test_validate_success_login_form" time="0.000" timestamp="2021-12-19T17:11:14">
		<error type="TypeError" message="login() got an unexpected keyword argument 'Email'"><![CDATA[Traceback (most recent call last):
  File "c:\users\hp\appdata\local\programs\python\python38\lib\unittest\case.py", line 60, in testPartExecutor
    yield
  File "c:\users\hp\appdata\local\programs\python\python38\lib\unittest\case.py", line 676, in run
    self._callTestMethod(testMethod)
  File "c:\users\hp\appdata\local\programs\python\python38\lib\unittest\case.py", line 633, in _callTestMethod
    method()
  File "c:\users\hp\desktop\builder\profiling\src\unittest\python\helloworld_tests.py", line 10, in test_validate_success_login_form
    form = login(Email='test@user.com', Password='just_a_test_user')
TypeError: login() got an unexpected keyword argument 'Email'
]]></error>
	</testcase>
</testsuite>
