{
  "errors": [],
  "failures": [
    {
      "test": "helloworld_tests.FlaskTestCase.test_correct_login",
      "traceback": "Traceback (most recent call last):\n  File \"c:\\users\\hp\\appdata\\local\\programs\\python\\python38\\lib\\unittest\\case.py\", line 60, in testPartExecutor\n    yield\n  File \"c:\\users\\hp\\appdata\\local\\programs\\python\\python38\\lib\\unittest\\case.py\", line 676, in run\n    self._callTestMethod(testMethod)\n  File \"c:\\users\\hp\\appdata\\local\\programs\\python\\python38\\lib\\unittest\\case.py\", line 633, in _callTestMethod\n    method()\n  File \"c:\\users\\hp\\desktop\\builder\\profiling\\src\\unittest\\python\\helloworld_tests.py\", line 17, in test_correct_login\n    self.assertIn(b'Invalid Email and/or Password', response.data)\n  File \"c:\\users\\hp\\appdata\\local\\programs\\python\\python38\\lib\\unittest\\case.py\", line 1179, in assertIn\n    self.fail(self._formatMessage(msg, standardMsg))\n  File \"c:\\users\\hp\\appdata\\local\\programs\\python\\python38\\lib\\unittest\\case.py\", line 753, in fail\n    raise self.failureException(msg)\nAssertionError: b'Invalid Email and/or Password' not found in b'<!DOCTYPE HTML PUBLIC \"-//W3C//DTD HTML 3.2 Final//EN\">\\n<title>400 Bad Request</title>\\n<h1>Bad Request</h1>\\n<p>The browser (or proxy) sent a request that this server could not understand.</p>\\n'\n"
    }
  ],
  "tests-run": 1
}